<?xml version="1.0" ?>
<robot name="robot" xmlns:xacro="http://www.ros.org/wiki/xacro">

<xacro:include filename="$(find robot_description)/urdf/materials.xacro" />
<xacro:include filename="$(find robot_description)/urdf/robot.trans" />
<xacro:include filename="$(find robot_description)/urdf/robot.gazebo" />


<xacro:property name="base_collision_height" value="0.5403669088914017"/>
<xacro:property name="base_mass" value="12.4385441416157"/>
<xacro:property name="base_mass_ixx" value="9.007417"/>
<xacro:property name="base_mass_iyy" value="2.398532"/>
<xacro:property name="base_mass_izz" value="2.911004"/>

<link name="base_link">
  <visual>
    <origin xyz="0 0 0" rpy="0 0 0"/>
    <geometry>
      <mesh filename="package://robot_description/meshes/base_link.stl" scale="0.001 0.001 0.001"/>
    </geometry>
    <material name="silver"/>
  </visual>
  <collision>
    <origin xyz="0 0 0" rpy="0 0 0"/>
    <geometry>
      <mesh filename="package://robot_description/meshes/base_link.stl" scale="0.001 0.001 0.001"/>
    </geometry>
  </collision>
</link>

<joint name="inertial_joint" type="fixed">
  <parent link="base_link"/>
  <child link="main_mass"/>
  <origin xyz="0 0 0" rpy="0 0 0"/>
</joint>  

<link name="main_mass" type="fixed">
  <inertial>
    <origin xyz="0 0 0" rpy="0 0 0"/>
    <mass value="${base_mass}"/>
    <inertia
      ixx="${base_mass_ixx}"  ixy="0.000000"  ixz="0.000000"
      iyy="${base_mass_iyy}"  iyz="0.000000"
      izz="${base_mass_izz}"/>
  </inertial>
</link>

<!-- 调用激光雷达 -->
<xacro:include filename="$(find robot_description)/urdf/VLP-16.urdf.xacro"/>
<xacro:VLP-16 
  parent="base_link" 
  name="velodyne" 
  topic="/velodyne_points" 
  hz="10" 
  samples="440"
  min_range="0.5"
  max_range="130" 
  gpu="true"
>
  <origin xyz="0.0 0.0 1.153" rpy="0 0 0" />
</xacro:VLP-16>

<joint name="back_right_wheel_joint" type="continuous">
  <origin xyz="-0.201052 -0.388969 0.064" rpy="0 0 0"/>
  <parent link="base_link"/>
  <child link="back_right_wheel"/>
  <axis xyz="0.0 1.0 0.0"/>
</joint>

<link name="back_right_wheel">
  <inertial>
    <origin xyz="1.993463346616764e-07 -0.010133233981134915 -3.8674692458273707e-07" rpy="0 0 0"/>
    <mass value="4.081557175543853"/>
    <inertia ixx="0.004756" iyy="0.008431" izz="0.004756" ixy="0.0" iyz="0.0" ixz="-0.0"/>
  </inertial>
  <visual>
    <origin xyz="0.201052 0.388969 -0.064" rpy="0 0 0"/>
    <geometry>
      <mesh filename="package://robot_description/meshes/back_right_wheel.stl" scale="0.001 0.001 0.001"/>
    </geometry>
    <material name="silver"/>
  </visual>
  <collision>
    <origin xyz="0.201052 0.388969 -0.064" rpy="0 0 0"/>
    <geometry>
      <mesh filename="package://robot_description/meshes/back_right_wheel.stl" scale="0.001 0.001 0.001"/>
    </geometry>
  </collision>
</link>


<joint name="back_left_wheel_joint" type="continuous">
  <origin xyz="-0.201052 0.391031 0.064" rpy="0 0 0"/>
  <parent link="base_link"/>
  <child link="back_left_wheel"/>
  <axis xyz="0.0 1.0 0.0"/>
</joint>

<link name="back_left_wheel">
  <inertial>
    <origin xyz="1.9934637884855277e-07 0.010132775871081967 -3.867469245411037e-07" rpy="0 0 0"/>
    <mass value="4.0815571755438596"/>
    <inertia ixx="0.004756" iyy="0.008431" izz="0.004756" ixy="0.0" iyz="0.0" ixz="0.0"/>
  </inertial>
  <visual>
    <origin xyz="0.201052 -0.391031 -0.064" rpy="0 0 0"/>
    <geometry>
      <mesh filename="package://robot_description/meshes/back_left_wheel.stl" scale="0.001 0.001 0.001"/>
    </geometry>
    <material name="silver"/>
  </visual>
  <collision>
    <origin xyz="0.201052 -0.391031 -0.064" rpy="0 0 0"/>
    <geometry>
      <mesh filename="package://robot_description/meshes/back_left_wheel.stl" scale="0.001 0.001 0.001"/>
    </geometry>
  </collision>
</link>



<joint name="front_left_wheel_joint" type="continuous">
  <origin xyz="0.198948 0.391031 0.064" rpy="0 0 0"/>
  <parent link="base_link"/>
  <child link="front_left_wheel"/>
  <axis xyz="0.0 1.0 0.0"/>
</joint>

<link name="front_left_wheel">
  <inertial>
    <origin xyz="1.993463788207972e-07 0.010132775871081856 -3.867469245411037e-07" rpy="0 0 0"/>
    <mass value="4.081557175543859"/>
    <inertia ixx="0.004756" iyy="0.008431" izz="0.004756" ixy="-0.0" iyz="-0.0" ixz="0.0"/>
  </inertial>
  <visual>
    <origin xyz="-0.198948 -0.391031 -0.064" rpy="0 0 0"/>
    <geometry>
      <mesh filename="package://robot_description/meshes/front_left_wheel.stl" scale="0.001 0.001 0.001"/>
    </geometry>
    <material name="silver"/>
  </visual>
  <collision>
    <origin xyz="-0.198948 -0.391031 -0.064" rpy="0 0 0"/>
    <geometry>
      <mesh filename="package://robot_description/meshes/front_left_wheel.stl" scale="0.001 0.001 0.001"/>
    </geometry>
  </collision>
</link>


<joint name="front_right_wheel_joint" type="continuous">
  <origin xyz="0.198948 -0.388969 0.064" rpy="0 0 0"/>
  <parent link="base_link"/>
  <child link="front_right_wheel"/>
  <axis xyz="0.0 1.0 0.0"/>
</joint>

<link name="front_right_wheel">
  <inertial>
    <origin xyz="1.9934633427309834e-07 -0.01013323398113486 -3.867469245688593e-07" rpy="0 0 0"/>
    <mass value="4.081557175543853"/>
    <inertia ixx="0.004756" iyy="0.008431" izz="0.004756" ixy="0.0" iyz="0.0" ixz="-0.0"/>
  </inertial>
  <visual>
    <origin xyz="-0.198948 0.388969 -0.064" rpy="0 0 0"/>
    <geometry>
      <mesh filename="package://robot_description/meshes/front_right_wheel.stl" scale="0.001 0.001 0.001"/>
    </geometry>
    <material name="silver"/>
  </visual>
  <collision>
    <origin xyz="-0.198948 0.388969 -0.064" rpy="0 0 0"/>
    <geometry>
      <mesh filename="package://robot_description/meshes/front_right_wheel.stl" scale="0.001 0.001 0.001"/>
    </geometry>
  </collision>
</link>

<!-- 添加imu连接 -->
<joint name="imu_fixed_joint" type="fixed">
  <origin xyz="0.0 0.0 0.923475" rpy="0 0 0"/>
  <parent link="base_link"/>
  <child link="imu_link"/>
</joint>

<link name="imu_link">
  <inertial>
    <origin xyz="-3.1964619419726226e-05 -3.009551236631383e-17 0.004668359474671813" rpy="0 0 0"/>
    <mass value="0.18887672743007808"/>
    <inertia ixx="4.3e-05" iyy="3.5e-05" izz="7.5e-05" ixy="0.0" iyz="0.0" ixz="0.0"/>
  </inertial>
  <visual>
    <origin xyz="-0.0 -0.0 -0.923475" rpy="0 0 0"/>
    <geometry>
      <mesh filename="package://robot_description/meshes/imu_link.stl" scale="0.001 0.001 0.001"/>
    </geometry>
    <material name="silver"/>
  </visual>
  <collision>
    <origin xyz="-0.0 -0.0 -0.923475" rpy="0 0 0"/>
    <geometry>
      <mesh filename="package://robot_description/meshes/imu_link.stl" scale="0.001 0.001 0.001"/>
    </geometry>
  </collision>
</link>

<link name="gps_link">
  <inertial>
    <mass value="0.1"/>
    <origin xyz="0 0 0" />
    <inertia ixx="0.01" iyy="0.01" izz="0.01" ixy="0.01" ixz="0.01" iyz="0.01"/>
  </inertial>
  <visual>
    <geometry>
      <sphere radius="0.01"/>
    </geometry>
    <material name="silver"/>
  </visual>
  <collision>
    <geometry>
      <sphere radius="0.1"/>
    </geometry>
  </collision>
  <sensor name="gps_sensor" type="gps">
    <update_rate>1.0</update_rate>
    <visualize>true</visualize>
    <gps>
      <position>0 0 0</position>
    </gps>
  </sensor>
</link>

<joint name="gps_link_joint" type="fixed">
  <parent link="base_link" />
  <child link="gps_link" />
  <origin xyz="0.0 0.0 0.8" rpy="0 0 0" />  <!-- 适当设置位置 -->
</joint>



</robot>
